Workbook

Sheet Sheet1
A1: 행 레이블 | B1: 코드 | C1: 제품명 | D1: 1월 | E1: 2월 | F1: 3월 | G1: 4월 | H1: 5월 | I1: 6월 | J1: 7월 | K1: 8월 | L1: 9월 | M1: 10월 | N1: 11월 | O1: 10월 | P1: 총합계 | S1: 1달판매량 | T1: 3달판매량 | U1: 현재고량 | V1: 현재고량박스 | X1: 단가 | Y1: 수입금액합계
A2: 0 | B2: 72004072 | C2: #072-4온즈 페인트-Gold | H2: -1 | J2: -1 | M2: -3 | P2: -5 | Y2: =SUM(Y3:Y400) -> 46346
B3: 720PT001 | C3: 파인트-#001-페인트-Black | H3: -10 | P3: -10
B4: 720PT005 | C4: 파인트-#005-페인트-White | H4: -10 | P4: -10
B5: 720PT101 | C5: 파인트-#101-페인트-Flat Black | H5: -10 | P5: -10
B6: 720PT105 | C6: 파인트-#105-페인트-Flat White | H6: -10 | P6: -10
A7: 1-1.레더페인트 | B7: 72001001 | C7: =VLOOKUP(B7,[1]제품리스트!$A$2:$J$1000,10,FALSE) -> #001-Paint 1oz Black | D7: -699 | E7: -653 | F7: -734 | G7: -781 | H7: -598 | I7: -581 | J7: -927 | K7: -646 | L7: -539 | M7: -856 | N7: -566 | O7: -24 | P7: -7604 | Q7: =VLOOKUP(B7,[1]제품리스트!$A$2:$J$1000,10,FALSE) -> #001-Paint 1oz Black | R7: =P7/11 -> -691.27273 | S7: =R7/-12 -> 57.606061 | T7: =S7*3 -> 172.81818 | U7: =VLOOKUP(B7,[1]재고수량!$A$13:$D$651,3,FALSE) -> #N/A | V7: =U7/12 -> #N/A | X7: =VLOOKUP(B7,[1]제품리스트!$A$2:$F$1110,5,FALSE) -> 16.2 | Y7: =W7*X7 -> 0
B8: 72001004 | C8: #004-레더페인트-Neutral | D8: -66 | E8: -50 | F8: -72 | G8: -78 | H8: -93 | I8: -65 | J8: -141 | K8: -78 | L8: -60 | M8: -127 | N8: -45 | P8: -875 | Q8: =VLOOKUP(B8,[1]제품리스트!$A$2:$J$1000,10,FALSE) -> #004-Paint 1oz Neutral | R8: =P8/11 -> -79.545455 | S8: =R8/-12 -> 6.6287879 | T8: =S8*3 -> 19.886364 | U8: =VLOOKUP(B8,[1]재고수량!$A$13:$D$651,3,FALSE) -> #N/A | V8: =U8/12 -> #N/A | W8: 20 | X8: =VLOOKUP(B8,[1]제품리스트!$A$2:$F$1110,5,FALSE) -> 16.2 | Y8: =W8*X8 -> 324
B9: 72001005 | C9: #005-레더페인트-White | D9: -537 | E9: -503 | F9: -499 | G9: -588 | H9: -536 | I9: -535 | J9: -680 | K9: -627 | L9: -532 | M9: -695 | N9: -364 | P9: -6096 | Q9: =VLOOKUP(B9,[1]제품리스트!$A$2:$J$1000,10,FALSE) -> #005-Paint 1oz White | R9: =P9/11 -> -554.18182 | S9: =R9/-12 -> 46.181818 | T9: =S9*3 -> 138.54545 | U9: =VLOOKUP(B9,[1]재고수량!$A$13:$D$651,3,FALSE) -> #N/A | V9: =U9/12 -> #N/A | X9: =VLOOKUP(B9,[1]제품리스트!$A$2:$F$1110,5,FALSE) -> 16.2 | Y9: =W9*X9 -> 0
B10: 72001014 | C10: #014-레더페인트-Brown | D10: -81 | E10: -63 | F10: -90 | G10: -72 | H10: -92 | I10: -94 | J10: -84 | K10: -122 | L10: -66 | M10: -146 | N10: -81 | P10: -991 | Q10: =VLOOKUP(B10,[1]제품리스트!$A$2:$J$1000,10,FALSE) -> #014-Paint 1oz Brown | R10: =P10/11 -> -90.090909 | S10: =R10/-12 -> 7.5075758 | T10: =S10*3 -> 22.522727 | U10: =VLOOKUP(B10,[1]재고수량!$A$13:$D$651,3,FALSE) -> #N/A | V10: =U10/12 -> #N/A | W10: 20 | X10: =VLOOKUP(B10,[1]제품리스트!$A$2:$F$1110,5,FALSE) -> 16.2 | Y10: =W10*X10 -> 324
B11: 72001015 | C11: #015-레더페인트-Chocolate | D11: -12 | E11: -27 | F11: -30 | G11: -26 | H11: -37 | I11: -27 | J11: -53 | K11: -43 | L11: -9 | M11: -87 | N11: -53 | P11: -404 | Q11: =VLOOKUP(B11,[1]제품리스트!$A$2:$J$1000,10,FALSE) -> #015-Paint 1oz Chocolate | R11: =P11/11 -> -36.727273 | S11: =R11/-12 -> 3.0606061 | T11: =S11*3 -> 9.1818182 | U11: =VLOOKUP(B11,[1]재고수량!$A$13:$D$651,3,FALSE) -> #N/A | V11: =U11/12 -> #N/A | W11: 20 | X11: =VLOOKUP(B11,[1]제품리스트!$A$2:$F$1110,5,FALSE) -> 16.2 | Y11: =W11*X11 -> 324
B12: 72001018 | C12: #018-레더페인트-DarkBrown | D12: -63 | E12: -78 | F12: -116 | G12: -92 | H12: -65 | I12: -111 | J12: -1 | K12: -131 | L12: -73 | M12: -161 | N12: -84 | P12: -975 | Q12: =VLOOKUP(B12,[1]제품리스트!$A$2:$J$1000,10,FALSE) -> #018-Paint 1oz DarkBrown | R12: =P12/11 -> -88.636364 | S12: =R12/-12 -> 7.3863636 | T12: =S12*3 -> 22.159091 | U12: =VLOOKUP(B12,[1]재고수량!$A$13:$D$651,3,FALSE) -> #N/A | V12: =U12/12 -> #N/A | W12: 20 | X12: =VLOOKUP(B12,[1]제품리스트!$A$2:$F$1110,5,FALSE) -> 16.2 | Y12: =W12*X12 -> 324
B13: 72001019 | C13: #019-레더페인트-English Tan | D13: -30 | E13: -26 | F13: -32 | G13: -17 | H13: -51 | I13: -22 | J13: -16 | K13: -25 | L13: -13 | M13: -45 | N13: -19 | P13: -296 | Q13: =VLOOKUP(B13,[1]제품리스트!$A$2:$J$1000,10,FALSE) -> #019-Paint 1oz English Tan | R13: =P13/11 -> -26.909091 | S13: =R13/-12 -> 2.2424242 | T13: =S13*3 -> 6.7272727 | U13: =VLOOKUP(B13,[1]재고수량!$A$13:$D$651,3,FALSE) -> #N/A | V13: =U13/12 -> #N/A | W13: 10 | X13: =VLOOKUP(B13,[1]제품리스트!$A$2:$F$1110,5,FALSE) -> 16.2 | Y13: =W13*X13 -> 162
B14: 72001021 | C14: #021-레더페인트-LightBrown | D14: -31 | E14: -44 | F14: -18 | G14: -36 | H14: -45 | I14: -40 | J14: -50 | K14: -34 | L14: -50 | M14: -32 | N14: -40 | P14: -420 | Q14: =VLOOKUP(B14,[1]제품리스트!$A$2:$J$1000,10,FALSE) -> #021-Paint 1oz LightBrown | R14: =P14/11 -> -38.181818 | S14: =R14/-12 -> 3.1818182 | T14: =S14*3 -> 9.5454545 | U14: =VLOOKUP(B14,[1]재고수량!$A$13:$D$651,3,FALSE) -> #N/A | V14: =U14/12 -> #N/A | W14: 10 | X14: =VLOOKUP(B14,[1]제품리스트!$A$2:$F$1110,5,FALSE) -> 16.2 | Y14: =W14*X14 -> 162
B15: 72001024 | C15: #024-레더페인트-Orange | D15: -71 | E15: -77 | F15: -148 | G15: -40 | H15: -89 | I15: -88 | J15: -159 | K15: -85 | L15: -74 | M15: -61 | N15: -51 | P15: -943 | Q15: =VLOOKUP(B15,[1]제품리스트!$A$2:$J$1000,10,FALSE) -> #024-Paint 1oz Orange | R15: =P15/11 -> -85.727273 | S15: =R15/-12 -> 7.1439394 | T15: =S15*3 -> 21.431818 | U15: =VLOOKUP(B15,[1]재고수량!$A$13:$D$651,3,FALSE) -> #N/A | V15: =U15/12 -> #N/A | W15: 20 | X15: =VLOOKUP(B15,[1]제품리스트!$A$2:$F$1110,5,FALSE) -> 16.2 | Y15: =W15*X15 -> 324
B16: 72001027 | C16: #027-레더페인트- SADDLE | D16: -7 | E16: -20 | F16: -12 | G16: -5 | H16: -29 | I16: -39 | J16: -13 | K16: -9 | L16: -8 | M16: -49 | N16: -12 | P16: -203 | Q16: =VLOOKUP(B16,[1]제품리스트!$A$2:$J$1000,10,FALSE) -> #027- Paint 1oz SADDLE | R16: =P16/11 -> -18.454545 | S16: =R16/-12 -> 1.5378788 | T16: =S16*3 -> 4.6136364 | U16: =VLOOKUP(B16,[1]재고수량!$A$13:$D$651,3,FALSE) -> #N/A | V16: =U16/12 -> #N/A | W16: 10 | X16: =VLOOKUP(B16,[1]제품리스트!$A$2:$F$1110,5,FALSE) -> 16.2 | Y16: =W16*X16 -> 162
B17: 72001029 | C17: #029-레더페인트- Tan | D17: -36 | E17: -31 | F17: -45 | G17: -16 | H17: -18 | I17: -59 | J17: -40 | K17: -28 | L17: -18 | M17: -31 | N17: -26 | P17: -348 | Q17: =VLOOKUP(B17,[1]제품리스트!$A$2:$J$1000,10,FALSE) -> #029- Paint 1oz Tan | R17: =P17/11 -> -31.636364 | S17: =R17/-12 -> 2.6363636 | T17: =S17*3 -> 7.9090909 | U17: =VLOOKUP(B17,[1]재고수량!$A$13:$D$651,3,FALSE) -> #N/A | V17: =U17/12 -> #N/A | W17: 10 | X17: =VLOOKUP(B17,[1]제품리스트!$A$2:$F$1110,5,FALSE) -> 16.2 | Y17: =W17*X17 -> 162
B18: 72001040 | C18: #040-레더페인트-BLUE | D18: -223 | E18: -114 | F18: -247 | G18: -148 | H18: -169 | I18: -195 | J18: -288 | K18: -238 | L18: -192 | M18: -152 | N18: -94 | P18: -2060 | Q18: =VLOOKUP(B18,[1]제품리스트!$A$2:$J$1000,10,FALSE) -> #040-Paint 1oz BLUE | R18: =P18/11 -> -187.27273 | S18: =R18/-12 -> 15.606061 | T18: =S18*3 -> 46.818182 | U18: =VLOOKUP(B18,[1]재고수량!$A$13:$D$651,3,FALSE) -> #N/A | V18: =U18/12 -> #N/A | W18: 40 | X18: =VLOOKUP(B18,[1]제품리스트!$A$2:$F$1110,5,FALSE) -> 16.2 | Y18: =W18*X18 -> 648
B19: 72001041 | C19: #041-레더페인트-LightBLUE | D19: -35 | E19: -56 | F19: -58 | G19: -47 | H19: -59 | I19: -83 | J19: -84 | K19: -46 | L19: -85 | M19: -34 | N19: -40 | P19: -627 | Q19: =VLOOKUP(B19,[1]제품리스트!$A$2:$J$1000,10,FALSE) -> #041-Paint 1oz LightBLUE | R19: =P19/11 -> -57 | S19: =R19/-12 -> 4.75 | T19: =S19*3 -> 14.25 | U19: =VLOOKUP(B19,[1]재고수량!$A$13:$D$651,3,FALSE) -> #N/A | V19: =U19/12 -> #N/A | W19: 20 | X19: =VLOOKUP(B19,[1]제품리스트!$A$2:$F$1110,5,FALSE) -> 16.2 | Y19: =W19*X19 -> 324
B20: 72001042 | C20: #042-레더페인트-NavyBlue | D20: -36 | E20: -75 | F20: -55 | G20: -62 | H20: -71 | I20: -75 | J20: -80 | K20: -63 | L20: -82 | M20: -45 | N20: -41 | P20: -685 | Q20: =VLOOKUP(B20,[1]제품리스트!$A$2:$J$1000,10,FALSE) -> #042-Paint 1oz NavyBlue | R20: =P20/11 -> -62.272727 | S20: =R20/-12 -> 5.1893939 | T20: =S20*3 -> 15.568182 | U20: =VLOOKUP(B20,[1]재고수량!$A$13:$D$651,3,FALSE) -> #N/A | V20: =U20/12 -> #N/A | W20: 20 | X20: =VLOOKUP(B20,[1]제품리스트!$A$2:$F$1110,5,FALSE) -> 16.2 | Y20: =W20*X20 -> 324
B21: 72001043 | C21: #043-레더페인트-Turgouise | D21: -26 | E21: -39 | F21: -29 | G21: -29 | H21: -36 | I21: -38 | J21: -33 | K21: -56 | L21: -15 | M21: -33 | N21: -24 | P21: -358 | Q21: =VLOOKUP(B21,[1]제품리스트!$A$2:$J$1000,10,FALSE) -> #043-Paint 1oz Turgouise | R21: =P21/11 -> -32.545455 | S21: =R21/-12 -> 2.7121212 | T21: =S21*3 -> 8.1363636 | U21: =VLOOKUP(B21,[1]재고수량!$A$13:$D$651,3,FALSE) -> #N/A | V21: =U21/12 -> #N/A | W21: 10 | X21: =VLOOKUP(B21,[1]제품리스트!$A$2:$F$1110,5,FALSE) -> 16.2 | Y21: =W21*X21 -> 162
... B34: 72001093 | C34: #093-레더페인트-Brick | D34: -9 | E34: -15 | F34: -29 | G34: -6 | H34: -23 | I34: -29 | J34: -42 | K34: -4 | L34: -7 | M34: -20 | N34: -15 | P34: -199 | Q34: =VLOOKUP(B34,[1]제품리스트!$A$2:$J$1000,10,FALSE) -> #093-Paint 1oz Brick | R34: =P34/11 -> -18.090909 | S34: =R34/-12 -> 1.5075758 | T34: =S34*3 -> 4.5227273 | U34: =VLOOKUP(B34,[1]재고수량!$A$13:$D$651,3,FALSE) -> #N/A | V34: =U34/12 -> #N/A | W34: 10 | X34: =VLOOKUP(B34,[1]제품리스트!$A$2:$F$1110,5,FALSE) -> 16.2 | Y34: =W34*X34 -> 162
B35: 72001101 | C35: #101-레더페인트-Flat Black | D35: -466 | E35: -439 | F35: -513 | G35: -648 | H35: -545 | I35: -543 | J35: -507 | K35: -548 | L35: -613 | M35: -637 | N35: -508 | O35: 24 | P35: -5943 | Q35: =VLOOKUP(B35,[1]제품리스트!$A$2:$J$1000,10,FALSE) -> #101-Paint 1oz Flat Black | R35: =P35/11 -> -540.27273 | S35: =R35/-12 -> 45.022727 | T35: =S35*3 -> 135.06818 | U35: =VLOOKUP(B35,[1]재고수량!$A$13:$D$651,3,FALSE) -> #N/A | V35: =U35/12 -> #N/A | X35: =VLOOKUP(B35,[1]제품리스트!$A$2:$F$1110,5,FALSE) -> 16.2 | Y35: =W35*X35 -> 0
B36: 72001105 | C36: #105-레더페인트-Flat White | D36: -294 | E36: -367 | F36: -501 | G36: -571 | H36: -485 | I36: -614 | J36: -585 | K36: -492 | L36: -360 | M36: -401 | N36: -318 | P36: -4988 | Q36: =VLOOKUP(B36,[1]제품리스트!$A$2:$J$1000,10,FALSE) -> #105-Paint 1oz Flat White | R36: =P36/11 -> -453.45455 | S36: =R36/-12 -> 37.787879 | T36: =S36*3 -> 113.36364 | U36: =VLOOKUP(B36,[1]재고수량!$A$13:$D$651,3,FALSE) -> #N/A | V36: =U36/12 -> #N/A | X36: =VLOOKUP(B36,[1]제품리스트!$A$2:$F$1110,5,FALSE) -> 16.2 | Y36: =W36*X36 -> 0
B37: 72001141 | C37: #141-레더페인트-Copper | D37: -15 | E37: -14 | F37: -10 | G37: -4 | H37: -31 | I37: -8 | J37: -10 | K37: -16 | L37: -2 | M37: -14 | N37: -19 | P37: -143 | Q37: =VLOOKUP(B37,[1]제품리스트!$A$2:$J$1000,10,FALSE) -> #141-Paint 1oz Copper | R37: =P37/11 -> -13 | S37: =R37/-12 -> 1.0833333 | T37: =S37*3 -> 3.25 | U37: =VLOOKUP(B37,[1]재고수량!$A$13:$D$651,3,FALSE) -> #N/A | V37: =U37/12 -> #N/A | W37: 5 | X37: =VLOOKUP(B37,[1]제품리스트!$A$2:$F$1110,5,FALSE) -> 16.2 | Y37: =W37*X37 -> 81
B38: 72001142 | C38: #142-레더페인트-Bronze | D38: -21 | E38: -33 | F38: -20 | G38: -1 | H38: -41 | I38: -27 | J38: -24 | K38: -14 | L38: -35 | M38: -36 | N38: -21 | P38: -273 | Q38: =VLOOKUP(B38,[1]제품리스트!$A$2:$J$1000,10,FALSE) -> #142-Paint 1oz Bronze | R38: =P38/11 -> -24.818182 | S38: =R38/-12 -> 2.0681818 | T38: =S38*3 -> 6.2045455 | U38: =VLOOKUP(B38,[1]재고수량!$A$13:$D$651,3,FALSE) -> #N/A | V38: =U38/12 -> #N/A | W38: 5 | X38: =VLOOKUP(B38,[1]제품리스트!$A$2:$F$1110,5,FALSE) -> 16.2 | Y38: =W38*X38 -> 81
B39: 72001143 | C39: #143-레더페인트-Pewter | D39: -12 | E39: -32 | F39: -16 | G39: -13 | H39: -33 | I39: -26 | J39: -21 | K39: -38 | L39: -21 | M39: -37 | N39: -28 | P39: -277 | Q39: =VLOOKUP(B39,[1]제품리스트!$A$2:$J$1000,10,FALSE) -> #143-Paint 1oz Pewter | R39: =P39/11 -> -25.181818 | S39: =R39/-12 -> 2.0984848 | T39: =S39*3 -> 6.2954545 | U39: =VLOOKUP(B39,[1]재고수량!$A$13:$D$651,3,FALSE) -> #N/A | V39: =U39/12 -> #N/A | W39: 5 | X39: =VLOOKUP(B39,[1]제품리스트!$A$2:$F$1110,5,FALSE) -> 16.2 | Y39: =W39*X39 -> 81
B40: 72001150 | C40: #150-레더페인트-SILVER | D40: -53 | E40: -50 | F40: -73 | G40: -74 | H40: -77 | I40: -74 | J40: -91 | K40: -107 | L40: -42 | M40: -73 | N40: -57 | P40: -771 | Q40: =VLOOKUP(B40,[1]제품리스트!$A$2:$J$1000,10,FALSE) -> #150-Paint 1oz SILVER | R40: =P40/11 -> -70.090909 | S40: =R40/-12 -> 5.8409091 | T40: =S40*3 -> 17.522727 | U40: =VLOOKUP(B40,[1]재고수량!$A$13:$D$651,3,FALSE) -> #N/A | V40: =U40/12 -> #N/A | W40: 20 | X40: =VLOOKUP(B40,[1]제품리스트!$A$2:$F$1110,5,FALSE) -> 16.2 | Y40: =W40*X40 -> 324
B41: 72001155 | C41: #155-레더페인트-Bone | D41: -17 | E41: -16 | F41: -7 | G41: -12 | H41: -21 | I41: -12 | J41: -38 | K41: -11 | L41: -24 | M41: -19 | N41: -15 | P41: -192 | Q41: =VLOOKUP(B41,[1]제품리스트!$A$2:$J$1000,10,FALSE) -> #155-Paint 1oz Bone | R41: =P41/11 -> -17.454545 | S41: =R41/-12 -> 1.4545455 | T41: =S41*3 -> 4.3636364 | U41: =VLOOKUP(B41,[1]재고수량!$A$13:$D$651,3,FALSE) -> #N/A | V41: =U41/12 -> #N/A | X41: =VLOOKUP(B41,[1]제품리스트!$A$2:$F$1110,5,FALSE) -> 16.2 | Y41: =W41*X41 -> 0
B42: 72001156 | C42: #156-레더페인트-Champagne | D42: -22 | E42: -34 | F42: -29 | G42: -7 | H42: -36 | I42: -49 | J42: -62 | K42: -24 | L42: -30 | M42: -28 | N42: -28 | P42: -349 | Q42: =VLOOKUP(B42,[1]제품리스트!$A$2:$J$1000,10,FALSE) -> #156-Paint 1oz Champagne | R42: =P42/11 -> -31.727273 | S42: =R42/-12 -> 2.6439394 | T42: =S42*3 -> 7.9318182 | U42: =VLOOKUP(B42,[1]재고수량!$A$13:$D$651,3,FALSE) -> #N/A | V42: =U42/12 -> #N/A | W42: 10 | X42: =VLOOKUP(B42,[1]제품리스트!$A$2:$F$1110,5,FALSE) -> 16.2 | Y42: =W42*X42 -> 162
B43: 72001157 | C43: #157-레더페인트-DarkBone | D43: -6 | E43: -14 | F43: -10 | G43: -4 | H43: -32 | I43: -1 | J43: -6 | K43: -32 | L43: -7 | M43: -21 | N43: -19 | P43: -152 | Q43: =VLOOKUP(B43,[1]제품리스트!$A$2:$J$1000,10,FALSE) -> #157-Paint 1oz DarkBone | R43: =P43/11 -> -13.818182 | S43: =R43/-12 -> 1.1515152 | T43: =S43*3 -> 3.4545455 | U43: =VLOOKUP(B43,[1]재고수량!$A$13:$D$651,3,FALSE) -> #N/A | V43: =U43/12 -> #N/A | X43: =VLOOKUP(B43,[1]제품리스트!$A$2:$F$1110,5,FALSE) -> 16.2 | Y43: =W43*X43 -> 0
B44: 72001159 | C44: #159-레더페인트-Mist | D44: -22 | E44: -20 | F44: -21 | G44: -24 | H44: -23 | I44: -44 | J44: -12 | K44: -35 | L44: -7 | M44: -26 | N44: -10 | P44: -244 | Q44: =VLOOKUP(B44,[1]제품리스트!$A$2:$J$1000,10,FALSE) -> #159-Paint 1oz Mist | R44: =P44/11 -> -22.181818 | S44: =R44/-12 -> 1.8484848 | T44: =S44*3 -> 5.5454545 | U44: =VLOOKUP(B44,[1]재고수량!$A$13:$D$651,3,FALSE) -> #N/A | V44: =U44/12 -> #N/A | W44: 10 | X44: =VLOOKUP(B44,[1]제품리스트!$A$2:$F$1110,5,FALSE) -> 16.2 | Y44: =W44*X44 -> 162
B45: 72001160 | C45: #160-레더페인트-Vanilla | D45: -25 | E45: -47 | F45: -36 | G45: -38 | H45: -47 | I45: -37 | J45: -71 | K45: -32 | L45: -31 | M45: -46 | N45: -32 | P45: -442 | Q45: =VLOOKUP(B45,[1]제품리스트!$A$2:$J$1000,10,FALSE) -> #160-Paint 1oz Vanilla | R45: =P45/11 -> -40.181818 | S45: =R45/-12 -> 3.3484848 | T45: =S45*3 -> 10.045455 | U45: =VLOOKUP(B45,[1]재고수량!$A$13:$D$651,3,FALSE) -> #N/A | V45: =U45/12 -> #N/A | W45: 10 | X45: =VLOOKUP(B45,[1]제품리스트!$A$2:$F$1110,5,FALSE) -> 16.2 | Y45: =W45*X45 -> 162
B46: 72001161 | C46: #161-레더페인트-Natural | D46: -4 | E46: -39 | F46: -13 | G46: -19 | H46: -23 | I46: -55 | J46: -16 | K46: -41 | L46: -26 | M46: -66 | N46: -20 | P46: -322 | Q46: =VLOOKUP(B46,[1]제품리스트!$A$2:$J$1000,10,FALSE) -> #161-Paint 1oz Natural | R46: =P46/11 -> -29.272727 | S46: =R46/-12 -> 2.4393939 | T46: =S46*3 -> 7.3181818 | U46: =VLOOKUP(B46,[1]재고수량!$A$13:$D$651,3,FALSE) -> #N/A | V46: =U46/12 -> #N/A | W46: 10 | X46: =VLOOKUP(B46,[1]제품리스트!$A$2:$F$1110,5,FALSE) -> 16.2 | Y46: =W46*X46 -> 162
B47: 72001162 | C47: #162-레더페인트-Cream | D47: -63 | E47: -70 | F47: -63 | G47: -80 | H47: -84 | I47: -40 | J47: -124 | K47: -81 | L47: -119 | M47: -75 | N47: -63 | P47: -862 | Q47: =VLOOKUP(B47,[1]제품리스트!$A$2:$J$1000,10,FALSE) -> #162-Paint 1oz Cream | R47: =P47/11 -> -78.363636 | S47: =R47/-12 -> 6.530303 | T47: =S47*3 -> 19.590909 | U47: =VLOOKUP(B47,[1]재고수량!$A$13:$D$651,3,FALSE) -> #N/A | V47: =U47/12 -> #N/A | W47: 20 | X47: =VLOOKUP(B47,[1]제품리스트!$A$2:$F$1110,5,FALSE) -> 16.2 | Y47: =W47*X47 -> 324
B48: 72001163 | C48: #163-레더페인트-CapazioTan | D48: -7 | E48: -19 | F48: -8 | G48: -11 | H48: -23 | I48: -32 | J48: -27 | K48: -7 | L48: -13 | M48: -28 | N48: -32 | P48: -207 | Q48: =VLOOKUP(B48,[1]제품리스트!$A$2:$J$1000,10,FALSE) -> #163-Paint 1oz CapazioTan | R48: =P48/11 -> -18.818182 | S48: =R48/-12 -> 1.5681818 | T48: =S48*3 -> 4.7045455 | U48: =VLOOKUP(B48,[1]재고수량!$A$13:$D$651,3,FALSE) -> #N/A | V48: =U48/12 -> #N/A | X48: =VLOOKUP(B48,[1]제품리스트!$A$2:$F$1110,5,FALSE) -> 16.2 | Y48: =W48*X48 -> 0
B49: 72001165 | C49: #165-레더페인트-BeigeTaupe | D49: -12 | E49: -40 | F49: -22 | G49: -2 | H49: -26 | I49: -7 | J49: -16 | K49: -19 | L49: -16 | M49: -23 | N49: -30 | P49: -213 | Q49: =VLOOKUP(B49,[1]제품리스트!$A$2:$J$1000,10,FALSE) -> #165-Paint 1oz BeigeTaupe | R49: =P49/11 -> -19.363636 | S49: =R49/-12 -> 1.6136364 | T49: =S49*3 -> 4.8409091 | U49: =VLOOKUP(B49,[1]재고수량!$A$13:$D$651,3,FALSE) -> #N/A | V49: =U49/12 -> #N/A | X49: =VLOOKUP(B49,[1]제품리스트!$A$2:$F$1110,5,FALSE) -> 16.2 | Y49: =W49*X49 -> 0
B50: 72001166 | C50: #166-레더페인트-GreyTaupe | D50: -3 | E50: -24 | F50: -11 | G50: -13 | H50: -25 | I50: -27 | J50: -22 | K50: -6 | L50: -5 | M50: -34 | N50: -33 | P50: -203 | Q50: =VLOOKUP(B50,[1]제품리스트!$A$2:$J$1000,10,FALSE) -> #166-Paint 1oz GreyTaupe | R50: =P50/11 -> -18.454545 | S50: =R50/-12 -> 1.5378788 | T50: =S50*3 -> 4.6136364 | U50: =VLOOKUP(B50,[1]재고수량!$A$13:$D$651,3,FALSE) -> #N/A | V50: =U50/12 -> #N/A | X50: =VLOOKUP(B50,[1]제품리스트!$A$2:$F$1110,5,FALSE) -> 16.2 | Y50: =W50*X50 -> 0
B51: 72001167 | C51: #167-레더페인트-Taupe | D51: -10 | E51: -31 | F51: -35 | G51: -15 | H51: -26 | I51: -27 | J51: -21 | K51: -9 | L51: -31 | M51: -36 | N51: -16 | P51: -257 | Q51: =VLOOKUP(B51,[1]제품리스트!$A$2:$J$1000,10,FALSE) -> #167-Paint 1oz Taupe | R51: =P51/11 -> -23.363636 | S51: =R51/-12 -> 1.9469697 | T51: =S51*3 -> 5.8409091 | U51: =VLOOKUP(B51,[1]재고수량!$A$13:$D$651,3,FALSE) -> #N/A | V51: =U51/12 -> #N/A | X51: =VLOOKUP(B51,[1]제품리스트!$A$2:$F$1110,5,FALSE) -> 16.2 | Y51: =W51*X51 -> 0
B52: 72001168 | C52: #168-레더페인트-DarkTaupe | D52: -12 | E52: -33 | F52: -39 | G52: -15 | H52: -39 | I52: -28 | J52: -26 | K52: -12 | L52: -24 | M52: -26 | N52: -17 | P52: -271 | Q52: =VLOOKUP(B52,[1]제품리스트!$A$2:$J$1000,10,FALSE) -> #168-Paint 1oz DarkTaupe | R52: =P52/11 -> -24.636364 | S52: =R52/-12 -> 2.0530303 | T52: =S52*3 -> 6.1590909 | U52: =VLOOKUP(B52,[1]재고수량!$A$13:$D$651,3,FALSE) -> #N/A | V52: =U52/12 -> #N/A | W52: 5 | X52: =VLOOKUP(B52,[1]제품리스트!$A$2:$F$1110,5,FALSE) -> 16.2 | Y52: =W52*X52 -> 81
...
