Workbook

Sheet Sheet1
C4: 1온즈 | D4: 4온즈
B5: 페인트 | C5: =18/16.5 -> 1.0909091 | D5: =28.8/27 -> 1.0666667 | H5: =1.8/12*1150*1.2 -> 207
B6: 네온 | C6: =19/16.8 -> 1.1309524 | D6: =32/28 -> 1.1428571
B7: 콜렉터 | C7: 0 | D7: 0
B8: 글리터 | C8: 0 | D8: 0 | H8: =4290*0.03 -> 128.7
B9: 메탈 | C9: =19/16.8 -> 1.1309524 | D9: 0
B10: 펄레슨트 | C10: =19/18.6 -> 1.0215054 | D10: 0 | H10: =7800*0.55 -> 4290
B11: 레더다이 | H11: =7800*0.57 -> 4446 | I11: =H10-H11 -> -156
H13: =1.5/12 -> 0.125
B14: 제품명 | C14: 과거 | D14: 현재 | E14: 인상율 | H14: =0.125*1150*1.2 -> 172.5
B15: 레더다이 | C15: 21 | D15: 24 | E15: =D15/C15 -> 1.1428571
B16: 스웨이드다이 | C16: 21 | D16: 24 | E16: =D16/C16 -> 1.1428571 | H16: =3/12*1150*1.2 -> 345
A17: 82004000 | B17: =VLOOKUP(A17,[1]제품리스트!$A$1:$I$1000,2,FALSE) -> 디글레이저 4온즈 | C17: =VLOOKUP(A17,[1]제품리스트!$A$1:$I$1000,5,FALSE) -> 20 | D17: =VLOOKUP(A17,[2]Sheet1!$A$1:$E$491,5,FALSE) -> 20 | E17: =D17/C17 -> 1
A18: 820PT000 | B18: =VLOOKUP(A18,[1]제품리스트!$A$1:$I$1000,2,FALSE) -> 디글레이저 파인트 | C18: =VLOOKUP(A18,[1]제품리스트!$A$1:$I$1000,5,FALSE) -> 5.7 | D18: =VLOOKUP(A18,[2]Sheet1!$A$1:$E$491,5,FALSE) -> 5.8 | E18: =D18/C18 -> 1.0175439
A19: 60004000 | B19: =VLOOKUP(A19,[1]제품리스트!$A$1:$I$1000,2,FALSE) -> 피니셔#600 아크릴피니셔 | C19: =VLOOKUP(A19,[1]제품리스트!$A$1:$I$1000,5,FALSE) -> 22.2 | D19: =VLOOKUP(A19,[2]Sheet1!$A$1:$E$491,5,FALSE) -> 24 | E19: =D19/C19 -> 1.0810811 | H19: =1.8/12*1150*1.2 -> 207
A20: 61504000 | B20: =VLOOKUP(A20,[1]제품리스트!$A$1:$I$1000,2,FALSE) -> 피니셔#615 새틴아크릴피니셔 하이글로스 | C20: =VLOOKUP(A20,[1]제품리스트!$A$1:$I$1000,5,FALSE) -> 22.2 | D20: =VLOOKUP(A20,[2]Sheet1!$A$1:$E$491,5,FALSE) -> 24 | E20: =D20/C20 -> 1.0810811
A21: 61004000 | B21: =VLOOKUP(A21,[1]제품리스트!$A$1:$I$1000,2,FALSE) -> 피니셔#610 아크릴피니셔 하이글로스 | C21: =VLOOKUP(A21,[1]제품리스트!$A$1:$I$1000,5,FALSE) -> 22.2 | D21: =VLOOKUP(A21,[2]Sheet1!$A$1:$E$491,5,FALSE) -> 24 | E21: =D21/C21 -> 1.0810811
A22: 60504000 | B22: =VLOOKUP(A22,[1]제품리스트!$A$1:$I$1000,2,FALSE) -> 피니셔#605 새틴아크릴피니셔 | C22: =VLOOKUP(A22,[1]제품리스트!$A$1:$I$1000,5,FALSE) -> 22.2 | D22: =VLOOKUP(A22,[2]Sheet1!$A$1:$E$491,5,FALSE) -> 24 | E22: =D22/C22 -> 1.0810811 | H22: =1.8/12*1150*1.2 -> 207
A23: 62004000 | B23: =VLOOKUP(A23,[1]제품리스트!$A$1:$I$1000,2,FALSE) -> 피니셔#620 매트아크릴피니셔 | C23: =VLOOKUP(A23,[1]제품리스트!$A$1:$I$1000,5,FALSE) -> 22.2 | D23: =VLOOKUP(A23,[2]Sheet1!$A$1:$E$491,5,FALSE) -> 24 | E23: =D23/C23 -> 1.0810811
A24: 60001000 | B24: =VLOOKUP(A24,[1]제품리스트!$A$1:$I$1000,2,FALSE) -> 피니셔1온즈#600 아크릴피니셔 | C24: =VLOOKUP(A24,[1]제품리스트!$A$1:$I$1000,5,FALSE) -> 13.32 | D24: =VLOOKUP(A24,[2]Sheet1!$A$1:$E$491,5,FALSE) -> 14.4 | E24: =D24/C24 -> 1.0810811
A25: 61501000 | B25: =VLOOKUP(A25,[1]제품리스트!$A$1:$I$1000,2,FALSE) -> 피니셔1온즈#615 새틴아크릴피니셔 하이글로스 | C25: =VLOOKUP(A25,[1]제품리스트!$A$1:$I$1000,5,FALSE) -> 13.32 | D25: =VLOOKUP(A25,[2]Sheet1!$A$1:$E$491,5,FALSE) -> 14.4 | E25: =D25/C25 -> 1.0810811
A26: 61001000 | B26: =VLOOKUP(A26,[1]제품리스트!$A$1:$I$1000,2,FALSE) -> 피니셔1온즈#610 아크릴피니셔 하이글로스 | C26: =VLOOKUP(A26,[1]제품리스트!$A$1:$I$1000,5,FALSE) -> 13.32 | D26: =VLOOKUP(A26,[2]Sheet1!$A$1:$E$491,5,FALSE) -> 14.4 | E26: =D26/C26 -> 1.0810811 | H26: =D26-C26 -> 1.08 | I26: =1.08/12*1150*1.2 -> 124.2
A27: 60501000 | B27: =VLOOKUP(A27,[1]제품리스트!$A$1:$I$1000,2,FALSE) -> 피니셔1온즈#605 새틴아크릴피니셔 | C27: =VLOOKUP(A27,[1]제품리스트!$A$1:$I$1000,5,FALSE) -> 13.32 | D27: =VLOOKUP(A27,[2]Sheet1!$A$1:$E$491,5,FALSE) -> 14.4 | E27: =D27/C27 -> 1.0810811
A28: 62001000 | B28: =VLOOKUP(A28,[1]제품리스트!$A$1:$I$1000,2,FALSE) -> 피니셔1온즈#620 매트아크릴피니셔 | C28: =VLOOKUP(A28,[1]제품리스트!$A$1:$I$1000,5,FALSE) -> 13.32 | D28: =VLOOKUP(A28,[2]Sheet1!$A$1:$E$491,5,FALSE) -> 14.4 | E28: =D28/C28 -> 1.0810811
A29: 84008000 | B29: =VLOOKUP(A29,[1]제품리스트!$A$1:$I$1000,2,FALSE) -> 이지클리너 8온즈 | C29: =VLOOKUP(A29,[1]제품리스트!$A$1:$I$1000,5,FALSE) -> 19.2 | D29: =VLOOKUP(A29,[2]Sheet1!$A$1:$E$491,5,FALSE) -> 20 | E29: =D29/C29 -> 1.0416667
A30: 84008KIT | B30: =VLOOKUP(A30,[1]제품리스트!$A$1:$I$1000,2,FALSE) -> 이지클리너 키트 | C30: =VLOOKUP(A30,[1]제품리스트!$A$1:$I$1000,5,FALSE) -> 5 | D30: =VLOOKUP(A30,[2]Sheet1!$A$1:$E$491,5,FALSE) -> 5.4 | E30: =D30/C30 -> 1.08
A31: 845WS000 | B31: =VLOOKUP(A31,[1]제품리스트!$A$1:$I$1000,2,FALSE) -> 올퍼포스 클리너 | C31: =VLOOKUP(A31,[1]제품리스트!$A$1:$I$1000,5,FALSE) -> 26 | D31: 26 | E31: =D31/C31 -> 1
A32: 84205000 | B32: =VLOOKUP(A32,[1]제품리스트!$A$1:$I$1000,2,FALSE) -> 폼텍스 클리너 5온즈 | C32: =VLOOKUP(A32,[1]제품리스트!$A$1:$I$1000,5,FALSE) -> 13.2 | D32: =VLOOKUP(A32,[2]Sheet1!$A$1:$E$491,5,FALSE) -> 16.8 | E32: =D32/C32 -> 1.2727273 | H32: =16.8/12*1150*1.2 -> 1932
A33: 84205KIT | B33: =VLOOKUP(A33,[1]제품리스트!$A$1:$I$1000,2,FALSE) -> 폼텍스 클리너키트 | C33: =VLOOKUP(A33,[1]제품리스트!$A$1:$I$1000,5,FALSE) -> 6.5 | D33: =VLOOKUP(A33,[2]Sheet1!$A$1:$E$491,5,FALSE) -> 7 | E33: =D33/C33 -> 1.0769231
A34: 851WS000 | B34: =VLOOKUP(A34,[1]제품리스트!$A$1:$I$1000,2,FALSE) -> 워터&스테인 리펠런트(방수제) | C34: =VLOOKUP(A34,[1]제품리스트!$A$1:$I$1000,5,FALSE) -> 26 | D34: =VLOOKUP(A34,[2]Sheet1!$A$1:$E$491,5,FALSE) -> 28 | E34: =D34/C34 -> 1.0769231
A35: 85205000 | B35: =VLOOKUP(A35,[1]제품리스트!$A$1:$I$1000,2,FALSE) -> 부트스프레이 | C35: =VLOOKUP(A35,[1]제품리스트!$A$1:$I$1000,5,FALSE) -> 28 | D35: =VLOOKUP(A35,[2]Sheet1!$A$1:$E$491,5,FALSE) -> 28 | E35: =D35/C35 -> 1
A36: 72201000 | B36: =VLOOKUP(A36,[1]제품리스트!$A$1:$I$1000,2,FALSE) -> [희석재]둘러-1온즈 | C36: =VLOOKUP(A36,[1]제품리스트!$A$1:$I$1000,5,FALSE) -> 30 | D36: =VLOOKUP(A36,[2]Sheet1!$A$1:$E$491,5,FALSE) -> 23 | E36: =D36/C36 -> 0.76666667
A37: 72204000 | B37: =VLOOKUP(A37,[1]제품리스트!$A$1:$I$1000,2,FALSE) -> [희석재]둘러-4온즈 | C37: =VLOOKUP(A37,[1]제품리스트!$A$1:$I$1000,5,FALSE) -> 54 | D37: =VLOOKUP(A37,[2]Sheet1!$A$1:$E$491,5,FALSE) -> 51.84 | E37: =D37/C37 -> 0.96
A38: 72001000 | B38: =VLOOKUP(A38,[1]제품리스트!$A$1:$I$1000,2,FALSE) -> [희석재]2-Thin | C38: =VLOOKUP(A38,[1]제품리스트!$A$1:$I$1000,5,FALSE) -> 16.2 | D38: =VLOOKUP(A38,[2]Sheet1!$A$1:$E$491,5,FALSE) -> #N/A | E38: =D38/C38 -> #N/A
A39: 72004000 | B39: =VLOOKUP(A39,[1]제품리스트!$A$1:$I$1000,2,FALSE) -> [희석재]2-Thin 4oz | C39: =VLOOKUP(A39,[1]제품리스트!$A$1:$I$1000,5,FALSE) -> 27 | D39: =VLOOKUP(A39,[2]Sheet1!$A$1:$E$491,5,FALSE) -> #N/A | E39: =D39/C39 -> #N/A
A40: 72201000soft | B40: =VLOOKUP(A40,[1]제품리스트!$A$1:$I$1000,2,FALSE) -> [희석재]2-소프트 1온즈 | C40: =VLOOKUP(A40,[1]제품리스트!$A$1:$I$1000,5,FALSE) -> 20.4 | D40: =VLOOKUP(A40,[2]Sheet1!$A$1:$E$491,5,FALSE) -> 20.4 | E40: =D40/C40 -> 1
A41: 72204000soft | B41: =VLOOKUP(A41,[1]제품리스트!$A$1:$I$1000,2,FALSE) -> [희석재]2-소프트 4온즈 | C41: =VLOOKUP(A41,[1]제품리스트!$A$1:$I$1000,5,FALSE) -> 40.8 | D41: =VLOOKUP(A41,[2]Sheet1!$A$1:$E$491,5,FALSE) -> 40.8 | E41: =D41/C41 -> 1
A42: 72201000hard | B42: =VLOOKUP(A42,[1]제품리스트!$A$1:$I$1000,2,FALSE) -> [희석재]2-하드 1온즈 | C42: =VLOOKUP(A42,[1]제품리스트!$A$1:$I$1000,5,FALSE) -> 20.4 | D42: =VLOOKUP(A42,[2]Sheet1!$A$1:$E$491,5,FALSE) -> 20.4 | E42: =D42/C42 -> 1
A43: 72204000hard | B43: =VLOOKUP(A43,[1]제품리스트!$A$1:$I$1000,2,FALSE) -> [희석재]2-하드 4온즈 | C43: =VLOOKUP(A43,[1]제품리스트!$A$1:$I$1000,5,FALSE) -> 40.8 | D43: =VLOOKUP(A43,[2]Sheet1!$A$1:$E$491,5,FALSE) -> 40.8 | E43: =D43/C43 -> 1
A44: 99103MO100 | B44: =VLOOKUP(A44,[1]제품리스트!$A$1:$I$1000,2,FALSE) -> 밍크오일 캔 | C44: =VLOOKUP(A44,[1]제품리스트!$A$1:$I$1000,5,FALSE) -> 16.4 | D44: =VLOOKUP(A44,[2]Sheet1!$A$1:$E$491,5,FALSE) -> 16.8 | E44: =D44/C44 -> 1.0243902
...
