Workbook

Sheet Sheet1
A1: 월 | B1: 연도 | C1: 모델명 | D1: 사이즈 | E1: 수량 | F1: 입출 | G1: 제품명 | H1: 실수량 | I1: 판매가 | J1: 판매가합계 | K1: 현지판매가 | L1: 수입가 | M1: 수입가합계 | N1: 구분 | O1: 인보이스넘버
A2: 7월 | B2: 42927 | C2: R01 | D2: 30 | E2: 1 | F2: 입 | G2: =VLOOKUP(C2,DATA!$A$2:$G$243,2,FALSE) -> Black/White Rope Laces | H2: =IF(F2="입",E2,-1*E2) -> 1 | I2: =VLOOKUP(C2,DATA!$A$2:$G$243,5,FALSE) -> 7000 | J2: =I2*E2 -> 7000 | K2: =VLOOKUP(C2,DATA!$A$2:$G$243,3,FALSE) -> 5.95 | L2: =VLOOKUP(C2,DATA!$A$2:$G$243,4,FALSE) -> 2.38 | M2: =L2*E2 -> 2.38 | N2: =VLOOKUP(C2,DATA!$A$2:$G$243,6,FALSE) -> Rope Laces | O2: 28605
A3: 7월 | B3: 42927 | C3: R01 | D3: 36 | E3: 3 | F3: 입 | G3: =VLOOKUP(C3,DATA!$A$2:$G$243,2,FALSE) -> Black/White Rope Laces | H3: =IF(F3="입",E3,-1*E3) -> 3 | I3: =VLOOKUP(C3,DATA!$A$2:$G$243,5,FALSE) -> 7000 | J3: =I3*E3 -> 21000 | K3: =VLOOKUP(C3,DATA!$A$2:$G$243,3,FALSE) -> 5.95 | L3: =VLOOKUP(C3,DATA!$A$2:$G$243,4,FALSE) -> 2.38 | M3: =L3*E3 -> 7.14 | N3: =VLOOKUP(C3,DATA!$A$2:$G$243,6,FALSE) -> Rope Laces | O3: 28605
A4: 7월 | B4: 42927 | C4: R01 | D4: 41 | E4: 3 | F4: 입 | G4: =VLOOKUP(C4,DATA!$A$2:$G$243,2,FALSE) -> Black/White Rope Laces | H4: =IF(F4="입",E4,-1*E4) -> 3 | I4: =VLOOKUP(C4,DATA!$A$2:$G$243,5,FALSE) -> 7000 | J4: =I4*E4 -> 21000 | K4: =VLOOKUP(C4,DATA!$A$2:$G$243,3,FALSE) -> 5.95 | L4: =VLOOKUP(C4,DATA!$A$2:$G$243,4,FALSE) -> 2.38 | M4: =L4*E4 -> 7.14 | N4: =VLOOKUP(C4,DATA!$A$2:$G$243,6,FALSE) -> Rope Laces | O4: 28605
A5: 7월 | B5: 42927 | C5: R01 | D5: 45 | E5: 3 | F5: 입 | G5: =VLOOKUP(C5,DATA!$A$2:$G$243,2,FALSE) -> Black/White Rope Laces | H5: =IF(F5="입",E5,-1*E5) -> 3 | I5: =VLOOKUP(C5,DATA!$A$2:$G$243,5,FALSE) -> 7000 | J5: =I5*E5 -> 21000 | K5: =VLOOKUP(C5,DATA!$A$2:$G$243,3,FALSE) -> 5.95 | L5: =VLOOKUP(C5,DATA!$A$2:$G$243,4,FALSE) -> 2.38 | M5: =L5*E5 -> 7.14 | N5: =VLOOKUP(C5,DATA!$A$2:$G$243,6,FALSE) -> Rope Laces | O5: 28605
A6: 7월 | B6: 42927 | C6: R01 | D6: 54 | E6: 1 | F6: 입 | G6: =VLOOKUP(C6,DATA!$A$2:$G$243,2,FALSE) -> Black/White Rope Laces | H6: =IF(F6="입",E6,-1*E6) -> 1 | I6: =VLOOKUP(C6,DATA!$A$2:$G$243,5,FALSE) -> 7000 | J6: =I6*E6 -> 7000 | K6: =VLOOKUP(C6,DATA!$A$2:$G$243,3,FALSE) -> 5.95 | L6: =VLOOKUP(C6,DATA!$A$2:$G$243,4,FALSE) -> 2.38 | M6: =L6*E6 -> 2.38 | N6: =VLOOKUP(C6,DATA!$A$2:$G$243,6,FALSE) -> Rope Laces | O6: 28605
A7: 7월 | B7: 42927 | C7: R02 | D7: 30 | E7: 1 | F7: 입 | G7: =VLOOKUP(C7,DATA!$A$2:$G$243,2,FALSE) -> Grey/Black Rope Laces | H7: =IF(F7="입",E7,-1*E7) -> 1 | I7: =VLOOKUP(C7,DATA!$A$2:$G$243,5,FALSE) -> 7000 | J7: =I7*E7 -> 7000 | K7: =VLOOKUP(C7,DATA!$A$2:$G$243,3,FALSE) -> 5.95 | L7: =VLOOKUP(C7,DATA!$A$2:$G$243,4,FALSE) -> 2.38 | M7: =L7*E7 -> 2.38 | N7: =VLOOKUP(C7,DATA!$A$2:$G$243,6,FALSE) -> Rope Laces | O7: 28605
A8: 7월 | B8: 42927 | C8: R02 | D8: 36 | E8: 3 | F8: 입 | G8: =VLOOKUP(C8,DATA!$A$2:$G$243,2,FALSE) -> Grey/Black Rope Laces | H8: =IF(F8="입",E8,-1*E8) -> 3 | I8: =VLOOKUP(C8,DATA!$A$2:$G$243,5,FALSE) -> 7000 | J8: =I8*E8 -> 21000 | K8: =VLOOKUP(C8,DATA!$A$2:$G$243,3,FALSE) -> 5.95 | L8: =VLOOKUP(C8,DATA!$A$2:$G$243,4,FALSE) -> 2.38 | M8: =L8*E8 -> 7.14 | N8: =VLOOKUP(C8,DATA!$A$2:$G$243,6,FALSE) -> Rope Laces | O8: 28605
A9: 7월 | B9: 42927 | C9: R02 | D9: 41 | E9: 3 | F9: 입 | G9: =VLOOKUP(C9,DATA!$A$2:$G$243,2,FALSE) -> Grey/Black Rope Laces | H9: =IF(F9="입",E9,-1*E9) -> 3 | I9: =VLOOKUP(C9,DATA!$A$2:$G$243,5,FALSE) -> 7000 | J9: =I9*E9 -> 21000 | K9: =VLOOKUP(C9,DATA!$A$2:$G$243,3,FALSE) -> 5.95 | L9: =VLOOKUP(C9,DATA!$A$2:$G$243,4,FALSE) -> 2.38 | M9: =L9*E9 -> 7.14 | N9: =VLOOKUP(C9,DATA!$A$2:$G$243,6,FALSE) -> Rope Laces | O9: 28605
A10: 7월 | B10: 42927 | C10: R02 | D10: 45 | E10: 3 | F10: 입 | G10: =VLOOKUP(C10,DATA!$A$2:$G$243,2,FALSE) -> Grey/Black Rope Laces | H10: =IF(F10="입",E10,-1*E10) -> 3 | I10: =VLOOKUP(C10,DATA!$A$2:$G$243,5,FALSE) -> 7000 | J10: =I10*E10 -> 21000 | K10: =VLOOKUP(C10,DATA!$A$2:$G$243,3,FALSE) -> 5.95 | L10: =VLOOKUP(C10,DATA!$A$2:$G$243,4,FALSE) -> 2.38 | M10: =L10*E10 -> 7.14 | N10: =VLOOKUP(C10,DATA!$A$2:$G$243,6,FALSE) -> Rope Laces | O10: 28605
A11: 7월 | B11: 42927 | C11: R02 | D11: 54 | E11: 1 | F11: 입 | G11: =VLOOKUP(C11,DATA!$A$2:$G$243,2,FALSE) -> Grey/Black Rope Laces | H11: =IF(F11="입",E11,-1*E11) -> 1 | I11: =VLOOKUP(C11,DATA!$A$2:$G$243,5,FALSE) -> 7000 | J11: =I11*E11 -> 7000 | K11: =VLOOKUP(C11,DATA!$A$2:$G$243,3,FALSE) -> 5.95 | L11: =VLOOKUP(C11,DATA!$A$2:$G$243,4,FALSE) -> 2.38 | M11: =L11*E11 -> 2.38 | N11: =VLOOKUP(C11,DATA!$A$2:$G$243,6,FALSE) -> Rope Laces | O11: 28605
A12: 7월 | B12: 42927 | C12: R03 | D12: 30 | E12: 1 | F12: 입 | G12: =VLOOKUP(C12,DATA!$A$2:$G$243,2,FALSE) -> Grey/White Rope Laces | H12: =IF(F12="입",E12,-1*E12) -> 1 | I12: =VLOOKUP(C12,DATA!$A$2:$G$243,5,FALSE) -> 7000 | J12: =I12*E12 -> 7000 | K12: =VLOOKUP(C12,DATA!$A$2:$G$243,3,FALSE) -> 5.95 | L12: =VLOOKUP(C12,DATA!$A$2:$G$243,4,FALSE) -> 2.38 | M12: =L12*E12 -> 2.38 | N12: =VLOOKUP(C12,DATA!$A$2:$G$243,6,FALSE) -> Rope Laces | O12: 28605
A13: 7월 | B13: 42927 | C13: R03 | D13: 36 | E13: 3 | F13: 입 | G13: =VLOOKUP(C13,DATA!$A$2:$G$243,2,FALSE) -> Grey/White Rope Laces | H13: =IF(F13="입",E13,-1*E13) -> 3 | I13: =VLOOKUP(C13,DATA!$A$2:$G$243,5,FALSE) -> 7000 | J13: =I13*E13 -> 21000 | K13: =VLOOKUP(C13,DATA!$A$2:$G$243,3,FALSE) -> 5.95 | L13: =VLOOKUP(C13,DATA!$A$2:$G$243,4,FALSE) -> 2.38 | M13: =L13*E13 -> 7.14 | N13: =VLOOKUP(C13,DATA!$A$2:$G$243,6,FALSE) -> Rope Laces | O13: 28605
... A490: 7월 | B490: 42927 | C490: W01 | D490: 54 | E490: 3 | F490: 입 | G490: =VLOOKUP(C490,DATA!$A$2:$G$243,2,FALSE) -> Black Waxed Shoe Laces | H490: =IF(F490="입",E490,-1*E490) -> 3 | I490: =VLOOKUP(C490,DATA!$A$2:$G$243,5,FALSE) -> 8000 | J490: =I490*E490 -> 24000 | K490: =VLOOKUP(C490,DATA!$A$2:$G$243,3,FALSE) -> 6.95 | L490: =VLOOKUP(C490,DATA!$A$2:$G$243,4,FALSE) -> 2.78 | M490: =L490*E490 -> 8.34 | N490: =VLOOKUP(C490,DATA!$A$2:$G$243,6,FALSE) -> Waxed Shoe Laces | O490: 28605
A491: 8월 | B491: 42971 | C491: r04 | D491: 30 | E491: 1 | F491: 출 | G491: =VLOOKUP(C491,DATA!$A$2:$G$243,2,FALSE) -> Black/Red Rope Laces | H491: =IF(F491="입",E491,-1*E491) -> -1 | I491: =VLOOKUP(C491,DATA!$A$2:$G$243,5,FALSE) -> 7000 | J491: =I491*E491 -> 7000 | K491: =VLOOKUP(C491,DATA!$A$2:$G$243,3,FALSE) -> 5.95 | L491: =VLOOKUP(C491,DATA!$A$2:$G$243,4,FALSE) -> 2.38 | M491: =L491*E491 -> 2.38 | N491: =VLOOKUP(C491,DATA!$A$2:$G$243,6,FALSE) -> Rope Laces
A492: 8월 | B492: 42971 | C492: x10 | D492: 54 | E492: 1 | F492: 출 | G492: =VLOOKUP(C492,DATA!$A$2:$G$243,2,FALSE) -> White - XIRopeLaces | H492: =IF(F492="입",E492,-1*E492) -> -1 | I492: =VLOOKUP(C492,DATA!$A$2:$G$243,5,FALSE) -> 7000 | J492: =I492*E492 -> 7000 | K492: =VLOOKUP(C492,DATA!$A$2:$G$243,3,FALSE) -> 5.95 | L492: =VLOOKUP(C492,DATA!$A$2:$G$243,4,FALSE) -> 2.38 | M492: =L492*E492 -> 2.38 | N492: =VLOOKUP(C492,DATA!$A$2:$G$243,6,FALSE) -> XI Rope Laces
A493: 8월 | B493: 42971 | C493: x05 | D493: 54 | E493: 1 | F493: 출 | G493: =VLOOKUP(C493,DATA!$A$2:$G$243,2,FALSE) -> Legend Blue - XIRopeLaces | H493: =IF(F493="입",E493,-1*E493) -> -1 | I493: =VLOOKUP(C493,DATA!$A$2:$G$243,5,FALSE) -> 7000 | J493: =I493*E493 -> 7000 | K493: =VLOOKUP(C493,DATA!$A$2:$G$243,3,FALSE) -> 5.95 | L493: =VLOOKUP(C493,DATA!$A$2:$G$243,4,FALSE) -> 2.38 | M493: =L493*E493 -> 2.38 | N493: =VLOOKUP(C493,DATA!$A$2:$G$243,6,FALSE) -> XI Rope Laces
A494: 8월 | B494: 42974 | C494: L07 | D494: 63 | E494: 1 | F494: 출 | G494: =VLOOKUP(C494,DATA!$A$2:$G$243,2,FALSE) -> Gold Luxury Leather Laces - GoldPlated | H494: =IF(F494="입",E494,-1*E494) -> -1 | I494: =VLOOKUP(C494,DATA!$A$2:$G$243,5,FALSE) -> 25000 | J494: =I494*E494 -> 25000 | K494: =VLOOKUP(C494,DATA!$A$2:$G$243,3,FALSE) -> 19.95 | L494: =VLOOKUP(C494,DATA!$A$2:$G$243,4,FALSE) -> 7.98 | M494: =L494*E494 -> 7.98 | N494: =VLOOKUP(C494,DATA!$A$2:$G$243,6,FALSE) -> Luxury Leather Laces
A495: 8월 | B495: 42978 | C495: f04 | D495: 63 | E495: 1 | F495: 출 | G495: =VLOOKUP(C495,DATA!$A$2:$G$243,2,FALSE) -> Royal Blue Shoe Laces | H495: =IF(F495="입",E495,-1*E495) -> -1 | I495: =VLOOKUP(C495,DATA!$A$2:$G$243,5,FALSE) -> 6000 | J495: =I495*E495 -> 6000 | K495: =VLOOKUP(C495,DATA!$A$2:$G$243,3,FALSE) -> 4.95 | L495: =VLOOKUP(C495,DATA!$A$2:$G$243,4,FALSE) -> 1.98 | M495: =L495*E495 -> 1.98 | N495: =VLOOKUP(C495,DATA!$A$2:$G$243,6,FALSE) -> Shoe Laces
A496: 9월 | B496: 42982 | C496: L07 | D496: 54 | E496: 1 | F496: 출 | G496: =VLOOKUP(C496,DATA!$A$2:$G$243,2,FALSE) -> Gold Luxury Leather Laces - GoldPlated | H496: =IF(F496="입",E496,-1*E496) -> -1 | I496: =VLOOKUP(C496,DATA!$A$2:$G$243,5,FALSE) -> 25000 | J496: =I496*E496 -> 25000 | K496: =VLOOKUP(C496,DATA!$A$2:$G$243,3,FALSE) -> 19.95 | L496: =VLOOKUP(C496,DATA!$A$2:$G$243,4,FALSE) -> 7.98 | M496: =L496*E496 -> 7.98 | N496: =VLOOKUP(C496,DATA!$A$2:$G$243,6,FALSE) -> Luxury Leather Laces
A497: 9월 | B497: 42984 | C497: F22 | D497: 45 | E497: 1 | F497: 출 | G497: =VLOOKUP(C497,DATA!$A$2:$G$243,2,FALSE) -> Beige Shoe Laces | H497: =IF(F497="입",E497,-1*E497) -> -1 | I497: =VLOOKUP(C497,DATA!$A$2:$G$243,5,FALSE) -> 6000 | J497: =I497*E497 -> 6000 | K497: =VLOOKUP(C497,DATA!$A$2:$G$243,3,FALSE) -> 4.95 | L497: =VLOOKUP(C497,DATA!$A$2:$G$243,4,FALSE) -> 1.98 | M497: =L497*E497 -> 1.98 | N497: =VLOOKUP(C497,DATA!$A$2:$G$243,6,FALSE) -> Shoe Laces
A498: 9월 | B498: 42985 | C498: O05 | D498: 63 | E498: 2 | F498: 출 | G498: =VLOOKUP(C498,DATA!$A$2:$G$243,2,FALSE) -> Grey - OvalSBLaces | H498: =IF(F498="입",E498,-1*E498) -> -2 | I498: =VLOOKUP(C498,DATA!$A$2:$G$243,5,FALSE) -> 5000 | J498: =I498*E498 -> 10000 | K498: =VLOOKUP(C498,DATA!$A$2:$G$243,3,FALSE) -> 3.95 | L498: =VLOOKUP(C498,DATA!$A$2:$G$243,4,FALSE) -> 1.58 | M498: =L498*E498 -> 3.16 | N498: =VLOOKUP(C498,DATA!$A$2:$G$243,6,FALSE) -> Oval SB Laces
A499: 9월 | B499: 42985 | C499: W01 | D499: 45 | E499: 1 | F499: 출 | G499: =VLOOKUP(C499,DATA!$A$2:$G$243,2,FALSE) -> Black Waxed Shoe Laces | H499: =IF(F499="입",E499,-1*E499) -> -1 | I499: =VLOOKUP(C499,DATA!$A$2:$G$243,5,FALSE) -> 8000 | J499: =I499*E499 -> 8000 | K499: =VLOOKUP(C499,DATA!$A$2:$G$243,3,FALSE) -> 6.95 | L499: =VLOOKUP(C499,DATA!$A$2:$G$243,4,FALSE) -> 2.78 | M499: =L499*E499 -> 2.78 | N499: =VLOOKUP(C499,DATA!$A$2:$G$243,6,FALSE) -> Waxed Shoe Laces
A500: 9월 | B500: 42985 | C500: F03 | D500: 54 | E500: 1 | F500: 출 | G500: =VLOOKUP(C500,DATA!$A$2:$G$243,2,FALSE) -> Red Shoe Laces | H500: =IF(F500="입",E500,-1*E500) -> -1 | I500: =VLOOKUP(C500,DATA!$A$2:$G$243,5,FALSE) -> 6000 | J500: =I500*E500 -> 6000 | K500: =VLOOKUP(C500,DATA!$A$2:$G$243,3,FALSE) -> 4.95 | L500: =VLOOKUP(C500,DATA!$A$2:$G$243,4,FALSE) -> 1.98 | M500: =L500*E500 -> 1.98 | N500: =VLOOKUP(C500,DATA!$A$2:$G$243,6,FALSE) -> Shoe Laces
A501: 9월 | B501: 42979 | C501: x03 | D501: 45 | E501: 2 | F501: 입 | G501: =VLOOKUP(C501,DATA!$A$2:$G$243,2,FALSE) -> Gamma Blue - XIRopeLaces | H501: =IF(F501="입",E501,-1*E501) -> 2 | I501: =VLOOKUP(C501,DATA!$A$2:$G$243,5,FALSE) -> 7000 | J501: =I501*E501 -> 14000 | K501: =VLOOKUP(C501,DATA!$A$2:$G$243,3,FALSE) -> 5.95 | L501: =VLOOKUP(C501,DATA!$A$2:$G$243,4,FALSE) -> 2.38 | M501: =L501*E501 -> 4.76 | N501: =VLOOKUP(C501,DATA!$A$2:$G$243,6,FALSE) -> XI Rope Laces
A502: 9월 | B502: 42979 | C502: x05 | D502: 54 | E502: 2 | F502: 입 | G502: =VLOOKUP(C502,DATA!$A$2:$G$243,2,FALSE) -> Legend Blue - XIRopeLaces | H502: =IF(F502="입",E502,-1*E502) -> 2 | I502: =VLOOKUP(C502,DATA!$A$2:$G$243,5,FALSE) -> 7000 | J502: =I502*E502 -> 14000 | K502: =VLOOKUP(C502,DATA!$A$2:$G$243,3,FALSE) -> 5.95 | L502: =VLOOKUP(C502,DATA!$A$2:$G$243,4,FALSE) -> 2.38 | M502: =L502*E502 -> 4.76 | N502: =VLOOKUP(C502,DATA!$A$2:$G$243,6,FALSE) -> XI Rope Laces
... A529: 9월 | B529: 42979 | C529: RF20 | D529: 54 | E529: 2 | F529: 입 | G529: =VLOOKUP(C529,DATA!$A$2:$G$243,2,FALSE) -> Olive - Reflective Flat Laces 2.0 | H529: =IF(F529="입",E529,-1*E529) -> 2 | I529: =VLOOKUP(C529,DATA!$A$2:$G$243,5,FALSE) -> 11000 | J529: =I529*E529 -> 22000 | K529: =VLOOKUP(C529,DATA!$A$2:$G$243,3,FALSE) -> 6.95 | L529: =VLOOKUP(C529,DATA!$A$2:$G$243,4,FALSE) -> 0 | M529: =L529*E529 -> 0 | N529: =VLOOKUP(C529,DATA!$A$2:$G$243,6,FALSE) -> Reflective Flat Laces
H530: =IF(F530="입",E530,-1*E530) -> 0
H531: =IF(F531="입",E531,-1*E531) -> 0
H532: =IF(F532="입",E532,-1*E532) -> 0
H533: =IF(F533="입",E533,-1*E533) -> 0
H534: =IF(F534="입",E534,-1*E534) -> 0
H535: =IF(F535="입",E535,-1*E535) -> 0
H536: =IF(F536="입",E536,-1*E536) -> 0
H537: =IF(F537="입",E537,-1*E537) -> 0
H538: =IF(F538="입",E538,-1*E538) -> 0
H539: =IF(F539="입",E539,-1*E539) -> 0
H540: =IF(F540="입",E540,-1*E540) -> 0
H541: =IF(F541="입",E541,-1*E541) -> 0
... H620: =IF(F620="입",E620,-1*E620) -> 0

Sheet Sheet2
A1: 월 | B1: (모두)
A3: 행 레이블 | B3: 제품명 | C3: 사이즈 | D3: 합계 : 실수량
A4: 3M01 | B4: Black 3M Reflective Rope Laces | C4: 30 | D4: 1
C5: 36 | D5: 2
C6: 41 | D6: 2
C7: 45 | D7: 2
C8: 54 | D8: 1
A9: 3M02 | B9: Blue 3M Reflective Rope Laces | C9: 30 | D9: 1
C10: 36 | D10: 2
C11: 45 | D11: 2
C12: 54 | D12: 1
A13: 3M03 | B13: White 3M Reflective Rope Laces | C13: 30 | D13: 1
C14: 36 | D14: 2
C15: 41 | D15: 2
C16: 45 | D16: 2
C17: 54 | D17: 1
A18: 3M04 | B18: Red 3M Reflective Rope Laces | C18: 30 | D18: 1
C19: 36 | D19: 2
C20: 45 | D20: 2
C21: 54 | D21: 1
A22: 3M05 | B22: Grey 3M/3M Reflective Rope Laces | C22: 54 | D22: 1
A23: 3M06 | B23: Olive 3M Reflective Rope Laces | C23: 36 | D23: 2
C24: 45 | D24: 2
C25: 54 | D25: 1
A26: 3M07 | B26: Volt 3M Reflective Rope Laces | C26: 36 | D26: 2
C27: 45 | D27: 2
C28: 54 | D28: 1
A29: 3M08 | B29: Mint 3M Reflective Rope Laces | C29: 30 | D29: 1
C30: 36 | D30: 2
C31: 45 | D31: 2
C32: 54 | D32: 1
A33: 3M09 | B33: Cove Blue 3M Reflective Rope Laces | C33: 30 | D33: 1
C34: 36 | D34: 2
C35: 45 | D35: 2
C36: 54 | D36: 1
A37: 3M10 | B37: Yellow 3M Reflective Rope Laces | C37: 45 | D37: 1
C38: 54 | D38: 1
A39: 3M11 | B39: Purple 3M Reflective Rope Laces | C39: 45 | D39: 1
C40: 54 | D40: 1
A41: 3M12 | B41: Orange 3M Reflective Rope Laces | C41: 54 | D41: 1
...

Sheet DATA
A1: 모델명 | B1: Item | C1: 현지판매가 | D1: 수입가 | E1: 판매가 | F1: 구분
A2: R01 | B2: Black/White Rope Laces | C2: 5.95 | D2: =C2*0.4 -> 2.38 | E2: 7000 | F2: Rope Laces | G2: RP-01 | H2: R01
A3: R02 | B3: Grey/Black Rope Laces | C3: 5.95 | D3: =C3*0.4 -> 2.38 | E3: 7000 | F3: Rope Laces | G3: RP-02 | H3: R02
A4: R03 | B4: Grey/White Rope Laces | C4: 5.95 | D4: =C4*0.4 -> 2.38 | E4: 7000 | F4: Rope Laces | G4: RP-03 | H4: R03
A5: R04 | B5: Black/Red Rope Laces | C5: 5.95 | D5: =C5*0.4 -> 2.38 | E5: 7000 | F5: Rope Laces | G5: RP-04 | H5: R04
A6: R05 | B6: Blue/White Rope Laces | C6: 5.95 | D6: =C6*0.4 -> 2.38 | E6: 7000 | F6: Rope Laces | G6: RP-05 | H6: R05
A7: R06 | B7: Red/White Rope Laces | C7: 5.95 | D7: =C7*0.4 -> 2.38 | E7: 7000 | F7: Rope Laces | G7: RP-06 | H7: R06
A8: R07 | B8: Blue/Black Rope Laces | C8: 5.95 | D8: =C8*0.4 -> 2.38 | E8: 7000 | F8: Rope Laces | G8: RP-07 | H8: R07
A9: R08 | B9: Mint/Black Rope Laces | C9: 5.95 | D9: =C9*0.4 -> 2.38 | E9: 7000 | F9: Rope Laces | G9: RP-08 | H9: R08
A10: R09 | B10: Oxford Tan Rope Laces | C10: 5.95 | D10: =C10*0.4 -> 2.38 | E10: 7000 | F10: Rope Laces | G10: RP-09 | H10: R09
A11: R10 | B11: Metallic Red/Black Rope Laces | C11: 5.95 | D11: =C11*0.4 -> 2.38 | E11: 7000 | F11: Rope Laces | G11: RP-10 | H11: R10
A12: R11 | B12: Metallic Gold/White Rope Laces | C12: 5.95 | D12: =C12*0.4 -> 2.38 | E12: 7000 | F12: Rope Laces | G12: RP-11 | H12: R11
A13: R12 | B13: Olive/Black Rope Laces | C13: 5.95 | D13: =C13*0.4 -> 2.38 | E13: 7000 | F13: Rope Laces | G13: RP-12 | H13: R12
... A192: W01 | B192: Black Waxed Shoe Laces | C192: 6.95 | D192: =C192*0.4 -> 2.78 | E192: 8000 | F192: Waxed Shoe Laces | G192: WAX-01 | H192: W01
A193: MF01 | B193: Grey/Black Multi-Color Flat Laces | C193: 5.95 | D193: =C193*0.4 -> 2.38 | E193: 11000 | F193: Multi-Color Flat Laces
A194: MF02 | B194: Black/Red Multi-Color Flat Laces | C194: 5.95 | E194: 11000 | F194: Multi-Color Flat Laces
A195: MF03 | B195: Black/White Multi-Color Flat Laces | C195: 5.95 | E195: 11000 | F195: Multi-Color Flat Laces
A196: MF04 | B196: Grey/White Multi-Color Flat Laces | C196: 5.95 | E196: 11000 | F196: Multi-Color Flat Laces
A197: MF05 | B197: Beige/White Multi-Color Flat Laces | C197: 5.95 | E197: 11000 | F197: Multi-Color Flat Laces
A198: RF17 | B198: Sapphire - Reflective Flat Laces 2.0 | C198: 6.95 | E198: 11000 | F198: Reflective Flat Laces
A199: RF18 | B199: Navy Blue - Reflective Flat Laces 2.0 | C199: 6.95 | E199: 11000 | F199: Reflective Flat Laces
A200: RF19 | B200: Olive - Reflective Flat Laces 1.0 | C200: 6.95 | E200: 11000 | F200: Reflective Flat Laces
A201: RF20 | B201: Olive - Reflective Flat Laces 2.0 | C201: 6.95 | E201: 11000 | F201: Reflective Flat Laces

Sheet 레이스랩재고표
A1: 월 | B1: (모두)
A3: 합계 : 실수량 | C3: 열 레이블
A4: 행 레이블 | B4: 제품명 | C4: 30 | D4: 36 | E4: 41 | F4: 45 | G4: 54 | H4: 63 | I4: 72 | J4: (비어 있음) | K4: 총합계
A5: 3M Inverse Rope Laces | C5: 2 | D5: 10 | E5: 4 | F5: 10 | G5: 8 | K5: 34
A6: I01 | B6: Black 3M Inverse Rope Laces | C6: 1 | D6: 2 | E6: 2 | F6: 2 | G6: 1 | K6: 8
A7: I02 | B7: White 3M Inverse Rope Laces | C7: 1 | D7: 2 | E7: 2 | F7: 2 | G7: 1 | K7: 8
A8: I03 | B8: Blue 3M Inverse Rope Laces | D8: 1 | F8: 1 | G8: 1 | K8: 3
A9: I04 | B9: Red 3M Inverse Rope Laces | D9: 1 | F9: 1 | G9: 1 | K9: 3
A10: I05 | B10: Charcoal 3M Inverse Rope Laces | D10: 1 | F10: 1 | G10: 1 | K10: 3
A11: I06 | B11: Mint 3M Inverse Rope Laces | D11: 1 | F11: 1 | G11: 1 | K11: 3
A12: I07 | B12: Cove Blue 3M Inverse Rope Laces | D12: 1 | F12: 1 | G12: 1 | K12: 3
A13: I08 | B13: Volt 3M Inverse Rope Laces | D13: 1 | F13: 1 | G13: 1 | K13: 3
A14: 3M Reflective Rope Laces | C14: 7 | D14: 19 | E14: 4 | F14: 21 | G14: 15 | K14: 66
A15: 3M01 | B15: Black 3M Reflective Rope Laces | C15: 1 | D15: 2 | E15: 2 | F15: 2 | G15: 1 | K15: 8
A16: 3M02 | B16: Blue 3M Reflective Rope Laces | C16: 1 | D16: 2 | F16: 2 | G16: 1 | K16: 6
A17: 3M03 | B17: White 3M Reflective Rope Laces | C17: 1 | D17: 2 | E17: 2 | F17: 2 | G17: 1 | K17: 8
A18: 3M04 | B18: Red 3M Reflective Rope Laces | C18: 1 | D18: 2 | F18: 2 | G18: 1 | K18: 6
A19: 3M05 | B19: Grey 3M/3M Reflective Rope Laces | G19: 1 | K19: 1
A20: 3M06 | B20: Olive 3M Reflective Rope Laces | D20: 2 | F20: 2 | G20: 1 | K20: 5
A21: 3M07 | B21: Volt 3M Reflective Rope Laces | D21: 2 | F21: 2 | G21: 1 | K21: 5
A22: 3M08 | B22: Mint 3M Reflective Rope Laces | C22: 1 | D22: 2 | F22: 2 | G22: 1 | K22: 6
A23: 3M09 | B23: Cove Blue 3M Reflective Rope Laces | C23: 1 | D23: 2 | F23: 2 | G23: 1 | K23: 6
A24: 3M10 | B24: Yellow 3M Reflective Rope Laces | F24: 1 | G24: 1 | K24: 2
A25: 3M11 | B25: Purple 3M Reflective Rope Laces | F25: 1 | G25: 1 | K25: 2
A26: 3M12 | B26: Orange 3M Reflective Rope Laces | G26: 1 | K26: 1
A27: 3M13 | B27: Pink 3M Reflective Rope Laces | C27: 1 | D27: 1 | F27: 1 | G27: 1 | K27: 4
A28: 3M14 | B28: Green 3M Reflective Rope Laces | D28: 1 | F28: 1 | G28: 1 | K28: 3
A29: 3M15 | B29: Sapphire 3M Reflective Rope Laces | D29: 1 | F29: 1 | G29: 1 | K29: 3
A30: Boot Laces | F30: 24 | G30: 24 | H30: 24 | I30: 8 | K30: 80
A31: B01 | B31: Black Boot Laces | F31: 3 | G31: 3 | H31: 3 | I31: 1 | K31: 10
A32: B02 | B32: Black/Brown Boot Laces | F32: 3 | G32: 3 | H32: 3 | I32: 1 | K32: 10
A33: B03 | B33: Black/Grey Boot Laces | F33: 3 | G33: 3 | H33: 3 | I33: 1 | K33: 10
A34: B04 | B34: Black/Hunter Green Boot Laces | F34: 3 | G34: 3 | H34: 3 | I34: 1 | K34: 10
A35: B05 | B35: Black/Tan Boot Laces | F35: 3 | G35: 3 | H35: 3 | I35: 1 | K35: 10
A36: B06 | B36: Brown Boot Laces | F36: 3 | G36: 3 | H36: 3 | I36: 1 | K36: 10
A37: B07 | B37: Brown/Beige Boot Laces | F37: 3 | G37: 3 | H37: 3 | I37: 1 | K37: 10
A38: B08 | B38: Rawhide Boot Laces | F38: 3 | G38: 3 | H38: 3 | I38: 1 | K38: 10
A39: Luxury Leather Laces | D39: 21 | F39: 24 | G39: 23 | H39: 20 | K39: 88
A40: L01 | B40: Black Luxury Leather Laces - GoldPlated | D40: 4 | F40: 5 | G40: 5 | H40: 4 | K40: 18
A41: L02 | B41: Black Luxury Leather Laces - GunmetalPlated | D41: 2 | F41: 3 | G41: 3 | H41: 2 | K41: 10
...
